Workbook

Sheet Présentation
A1: Base MAS - INSEE mise à jour 2023
A3: Onget disponible | B3: Annee | D3: Description | E3: Lien vers le dictionnaire de données
A4: POP | B4: 2023 | D4: Contient des indicateurs détaillés sur la POPULATION de Roubaix selon le sexe, l'âge en tranches, la catégorie socio-professionnelle, en tenant compte de la population étrangère et de la population immigrée. | E4: https://www.insee.fr/fr/statistiques/9054332
A5: ACT RES | B5: 2023 | D5: Contient des indicateurs détaillés sur les caractéristiques des ACTIVITES DES RESIDENTS, des SALARIES et non-salariés selon le sexe, l’âge par tranches et la catégorie socio-professionnelles. | E5: https://www.insee.fr/fr/statistiques/9040859
A6: COU FAM MÉNAGES | B6: 2023 | D6: Contient des indicateurs détaillés sur lescaracteristiques des COUPLES, FAMILLES, MENAGES, (nombre d'enfants). | E6: https://www.insee.fr/fr/statistiques/9058978
A7: DIP FORMATION | B7: 2023 | D7: Contient des indicateurs détaillés les DIPLOMES ET FORMATION, la SCOLARISATION et les niveaux de DIPLOMES, les personnes non scolarisées de 15 à ou plus selon le sexe. | E7: https://www.insee.fr/fr/statistiques/9054820
A8: LOG | B8: 2023 | D8: Contient des indicateurs détaillés sur des LOGEMENTS, la possession d'une voiture ainsi que le parc de logements. | E8: https://www.insee.fr/fr/statistiques/9061333
A9: PETITE ENFANCE | B9: 2022 | D9: Contient des indicateurs du nombre d'enfants de 0 à 17 ans | E9: https://www.insee.fr/fr/statistiques/8647104
A10: CAF | B10: 2024 | C10: au 31/12/2024 | D10: Contient des indicateurs sur les bénéficiaires des prestations légales versées par les CAF à l'Iris | E10: https://www.insee.fr/fr/statistiques/8682393
A11: CNAM | B11: 2025 | C11: au 01/01/2025 | D11: Contient des indicateurs sur les bénéficiaires du régime général de l'assurance maladie ainsi que sur les bénéficiaires de la Complémentaire Santé Solidaire (C2S) issus des fichiers des Caisses Primaires d’Assurance Maladie (CPAM). | E11: https://www.insee.fr/fr/statistiques/8736938
A12: DEFM | B12: 2024 | C12: au 31/12/2024 | D12: Contient des indicateurs sur les demandeurs d'emploi à l'Iris (Pôle Emploi-Dares) | E12: https://www.insee.fr/fr/statistiques/8644875
A13: RPLS | B13: 2025 | C13: au 01/01/2025 | D13: Contient des indicateurs sur le Parc des Logements Locatifs des Bailleurs Sociaux à l'Iris | E13: https://www.insee.fr/fr/statistiques/9057420
A15: Précision
A16: # Les données INSEE sont à l'échelle des IRIS
A17: Dans les onglets, chaque iris correpond à une zone des découpages étudiés. Les differents zonages proposés ne se superposant pas au iris, il s 'agit donc d'une interprestation . Il a donc une marge d’erreur. Des indicateurs supplémentaires calculés sont disponibles à la fin des feuilles (tout à droite) sous fond orange
A18: L'ensemble des variables et définitions sont présentes sur le site de l'INSEE | E18: https://www.insee.fr/fr/information/2008354
A19: # Des applications dédiées sont également disponibles sur le portail SIG | E19: https://carto.ville-roubaix.fr
A20: https://carto.ville-roubaix.fr/portal/apps/MapSeries/index.html?appid=439897abe91f40e29fa8d4ca5483c55b
A21: # L'INSEE met également à disposition un dossier complet à l'échelle de la commune
A22: https://www.insee.fr/fr/statistiques/2011101?geo=COM-59512
A23: Pour toutes questions, contacter le service sig : sig@ville-roubaix.fr
A25: Mise a jour tous les ans entre octobre et decembre pour le recensement avec un decalage de 3 ans .
A26: Mise a jour annuelle pour caf cnam DEFEM RPLS

Sheet Portrait Roubaix
B2: Portrait de Roubaix · 2023
B3: Chiffres clés de Roubaix (ensemble des IRIS), toutes sources du classeur confondues. Chaque indicateur indique sa source et son année.
B5: DÉMOGRAPHIE | E5: EMPLOI ET FORMATION | H5: REVENUS ET PRESTATIONS | K5: LOGEMENT
B7: Population, densité, âges, sexe, nationalité, ménages et familles (monoparentales, nombreuses). | E7: Activité, emploi, chômage, diplômes de la population non scolarisée et demandeurs d'emploi. | H7: Revenus et pauvreté (Filosofi 2021, valeurs figées), allocataires CAF, RSA, AAH et complémentaire santé solidaire (CNAM). | K7: Parc, vacance, typologie, statut d'occupation, logements sociaux, ancienneté et suroccupation.
B8: Habitants | C8: =SUM('POP 2023'!$D$3:$D$40) | E8: Actifs (15-64 ans) | F8: =SUM('ACT RES 2023'!$P$3:$P$40) | H8: Niveau de vie médian | I8: 16080 | K8: Logements | L8: =SUM('LOG 2023'!$D$3:$D$40)
B9: RP 2023 · onglet POP 2023 | E9: RP 2023 · onglet ACT RES 2023 | H9: Filosofi 2021 · valeur figée · Roubaix | K9: RP 2023 · onglet LOG 2023
B10: Habitants au km² | C10: =IFERROR((SUM('POP 2023'!$D$3:$D$40))/(SUM('POP 2023'!$BL$3:$BL$40)),"") | E10: Taux d'emploi (15-64 ans) | F10: =IFERROR((SUM('ACT RES 2023'!$AB$3:$AB$40))/(SUM('ACT RES 2023'!$D$3:$D$40)),"") | H10: Taux de pauvreté (seuil de 60 % du niveau de vie médian) | I10: 47.4 | K10: Résidences principales | L10: =SUM('LOG 2023'!$E$3:$E$40)
B11: RP 2023 · onglet POP 2023 | E11: RP 2023 · onglet ACT RES 2023 | H11: Filosofi 2021 · valeur figée · Roubaix | K11: RP 2023 · onglet LOG 2023
B12: Moins de 20 ans | C12: =IFERROR((SUM('POP 2023'!$P$3:$P$40))/(SUM('POP 2023'!$D$3:$D$40)),"") | E12: Taux de chômage (15-64 ans) | F12: =IFERROR((SUM('ACT RES 2023'!$AN$3:$AN$40))/(SUM('ACT RES 2023'!$P$3:$P$40)),"") | H12: Allocataires CAF | I12: =SUM('CAF 2024'!$D$3:$D$40) | K12: Logements vacants | L12: =IFERROR((SUM('LOG 2023'!$G$3:$G$40))/(SUM('LOG 2023'!$D$3:$D$40)),"")
B13: RP 2023 · onglet POP 2023 | E13: RP 2023 · onglet ACT RES 2023 | H13: CAF 2024 · onglet CAF 2024 | K13: RP 2023 · onglet LOG 2023
B14: 65 ans ou plus | C14: =IFERROR((SUM('POP 2023'!$R$3:$R$40))/(SUM('POP 2023'!$D$3:$D$40)),"") | E14: Taux de chômage des 15-24 ans | F14: =IFERROR((SUM('ACT RES 2023'!$AO$3:$AO$40))/(SUM('ACT RES 2023'!$Q$3:$Q$40)),"") | H14: Population couverte par la CAF | I14: =IFERROR((SUM('CAF 2024'!$E$3:$E$40))/(SUM('CAF 2024'!$Z$3:$Z$40)),"") | K14: Maisons | L14: =IFERROR((SUM('LOG 2023'!$H$3:$H$40))/(SUM('LOG 2023'!$D$3:$D$40)),"")
B15: RP 2023 · onglet POP 2023 | E15: RP 2023 · onglet ACT RES 2023 | H15: CAF 2024 · onglet CAF 2024 | K15: RP 2023 · onglet LOG 2023
B16: Femmes | C16: =IFERROR((SUM('POP 2023'!$X$3:$X$40))/(SUM('POP 2023'!$D$3:$D$40)),"") | E16: Salariés en CDI ou fonction publique | F16: =IFERROR((SUM('ACT RES 2023'!$BV$3:$BV$40))/(SUM('ACT RES 2023'!$BH$3:$BH$40)),"") | H16: Allocataires CAF au RSA socle | I16: =IFERROR((SUM('CAF 2024'!$X$3:$X$40))/(SUM('CAF 2024'!$D$3:$D$40)),"") | K16: Propriétaires occupants | L16: =IFERROR((SUM('LOG 2023'!$AH$3:$AH$40))/(SUM('LOG 2023'!$E$3:$E$40)),"")
B17: RP 2023 · onglet POP 2023 | E17: RP 2023 · onglet ACT RES 2023 | H17: CAF 2024 · onglet CAF 2024 | K17: RP 2023 · onglet LOG 2023
B18: Étrangers | C18: =IFERROR((SUM('POP 2023'!$BE$3:$BE$40))/(SUM('POP 2023'!$D$3:$D$40)),"") | E18: Sans diplôme ou CEP (15 ans ou plus non scolarisés) | F18: =IFERROR((SUM('DIP FORMATION 2023'!$S$3:$S$40))/(SUM('DIP FORMATION 2023'!$R$3:$R$40)),"") | H18: Allocataires CAF mono-parents | I18: =IFERROR((SUM('CAF 2024'!$G$3:$G$40))/(SUM('CAF 2024'!$D$3:$D$40)),"") | K18: Locataires HLM | L18: =IFERROR((SUM('LOG 2023'!$AJ$3:$AJ$40))/(SUM('LOG 2023'!$E$3:$E$40)),"")
B19: RP 2023 · onglet POP 2023 | E19: RP 2023 · onglet DIP FORMATION 2023 | H19: CAF 2024 · onglet CAF 2024 | K19: RP 2023 · onglet LOG 2023
B20: Immigrés | C20: =IFERROR((SUM('POP 2023'!$BF$3:$BF$40))/(SUM('POP 2023'!$D$3:$D$40)),"") | E20: Diplômés du supérieur (15 ans ou plus non scolarisés) | F20: =IFERROR((SUM('DIP FORMATION 2023'!$W$3:$W$40)+SUM('DIP FORMATION 2023'!$X$3:$X$40)+SUM('DIP FORMATION 2023'!$Y$3:$Y$40))/(SUM('DIP FORMATION 2023'!$R$3:$R$40)),"") | H20: Allocataires de l'AAH | I20: =SUM('CAF 2024'!$V$3:$V$40) | K20: Résidences en suroccupation | L20: =IFERROR((SUM('LOG 2023'!$AY$3:$AY$40)+SUM('LOG 2023'!$AZ$3:$AZ$40))/(SUM('LOG 2023'!$E$3:$E$40)),"")
B21: RP 2023 · onglet POP 2023 | E21: RP 2023 · onglet DIP FORMATION 2023 | H21: CAF 2024 · onglet CAF 2024 | K21: RP 2023 · onglet LOG 2023
B22: Enfants de 0 à 17 ans | C22: =SUM('PETITE ENFANCE 2022'!$V$3:$V$40) | E22: Demandeurs d'emploi (cat. ABC) | F22: =SUM('DEFM 2024'!$G$3:$G$40) | H22: Bénéficiaires de la C2S non participative | I22: =IFERROR((SUM('CNAM 2025'!$M$3:$M$40))/(SUM('CNAM 2025'!$D$3:$D$40)),"") | K22: Ménages avec au moins une voiture | L22: =IFERROR((SUM('LOG 2023'!$AR$3:$AR$40))/(SUM('LOG 2023'!$AB$3:$AB$40)),"")
B23: RP (fichier détail) 2022 · onglet PETITE ENFANCE 2022 | E23: France Travail 2024 · onglet DEFM 2024 | H23: CNAM 2025 · onglet CNAM 2025 | K23: RP 2023 · onglet LOG 2023
B24: Ménages | C24: =SUM('COU FAM 2023'!$D$3:$D$40) | E24: Demandeurs ABC de moins de 26 ans | F24: =IFERROR((SUM('DEFM 2024'!$L$3:$L$40))/(SUM('DEFM 2024'!$G$3:$G$40)),"") | H24: Bénéficiaires de la C2S participative | I24: =IFERROR((SUM('CNAM 2025'!$U$3:$U$40))/(SUM('CNAM 2025'!$D$3:$D$40)),"") | K24: Logements sociaux (RPLS) | L24: =SUM('RPLS 2025'!$D$3:$D$40)
B25: RP 2023 · onglet COU FAM 2023 | E25: France Travail 2024 · onglet DEFM 2024 | H25: CNAM 2025 · onglet CNAM 2025 | K25: RPLS 2025 · onglet RPLS 2025
B26: Taille moyenne des ménages | C26: =IFERROR((SUM('COU FAM 2023'!$M$3:$M$40))/(SUM('COU FAM 2023'!$D$3:$D$40)),"") | E26: Demandeurs ABC depuis 2 ans ou plus | F26: =IFERROR((SUM('DEFM 2024'!$AR$3:$AR$40))/(SUM('DEFM 2024'!$G$3:$G$40)),"")
B27: RP 2023 · onglet COU FAM 2023 | E27: France Travail 2024 · onglet DEFM 2024
B28: Familles monoparentales | C28: =IFERROR((SUM('COU FAM 2023'!$AT$3:$AT$40))/(SUM('COU FAM 2023'!$AR$3:$AR$40)),"")
B29: RP 2023 · onglet COU FAM 2023
B30: Familles nombreuses (3 enfants ou plus) | C30: =IFERROR((SUM('COU FAM 2023'!$AY$3:$AY$40)+SUM('COU FAM 2023'!$AZ$3:$AZ$40))/(SUM('COU FAM 2023'!$AR$3:$AR$40)),"")
B31: RP 2023 · onglet COU FAM 2023
B33: À savoir
B34: • Les parts et taux sont recalculés sur Roubaix entière (somme des IRIS), pas en moyenne des IRIS.
B35: • Les valeurs sont des formules : elles suivent les onglets du classeur. Cliquer sur une source ouvre l'onglet.
B36: • Revenus Filosofi 2021 (Roubaix) : valeurs figées pour comparaison, les onglets Filosofi étant retirés (données trop anciennes).

Sheet Detail calcul
A1: Base MAS - INSEE mise à jour 2023
A2: Details sur les calculs de la population | B2: Details sur les calculs du logement | C2: Details sur les calculs des activités des résidents | D2: Details sur les calculs des couples-familles-ménages | E2: Details sur les calculs des diplômes et formations | F2: Details sur les calculs des demandeurs d'emploi | G2: Details sur les calculs des bénéficiaires de la CAF | H2: Details sur les calculs des bénéficiaires de la CNAM
A3: Superficie en hectares (POP) -> Superficie en km² * 100 | B3: Superficie en hectares (LOG) -> Superficie en km² * 100 | C3: Population (ACT RES) -> Population (feuille POP) | D3: Part des ménages avec famille(s) (%) -> Ménages avec famille(s) * 100 / Ménages | E3: Part pop 15 ans et plus non scol sans dip ou CEP max (%) -> Pop 15 ans ou plus non scol. Sans diplôme ou CEP * 100 / Pop 15 ans ou plus non scolarisée | F3: Population (DEFM) -> Population (feuille POP) | G3: Population (CAF) -> Population (feuille POP) | H3: Part de la population couverte bénéficiaire de la C2S non participative (%) -> Population couverte bénéficiaire de la C2S non participative (ex-CMUC) * 100 / Population couverte bénéficiaire du régime général (non calculé : variable absente de ce millésime)
A4: Densité de population en hab/km² -> Population / Superficie en km² | B4: Densité de logements au km² -> Logements / Superficie en km² | C4: Part de la population en âge de travailler (%) -> Pop 15-64 ans * 100 / Population (ACT RES) | D4: Part des ménages famille couple avec enfant(s) (%) -> Mén fam princ Couple avec enfant(s) * 100 / Ménages | E4: Pop 15 ans ou plus non scol dipl Ens Sup -> Pop 15 ans ou plus non scol. Enseignement sup de niveau bac + 2 + Pop 15 ans ou plus non scol. Enseignement sup de niveau bac + 3 ou 4 + Pop 15 ans ou plus non scol. Enseignement sup de niveau bac + 5 ou plus | F4: Part des DEFM dans la population totale (%) -> DEFM * 100 / Population (DEFM) | G4: Part de la population couverte par une allocation CAF (%) -> Personnes couvertes * 100 / Population (CAF) | H4: Part des bénéficiaires de la C2S non participative de moins de 18 ans (%) -> Bénéficiaires de la C2S non participative (ex-CMUC) de moins de 18 ans * 100 / Population couverte bénéficiaire de la C2S non participative (ex-CMUC) (non calculé : variable absente de ce millésime)
A5: Part de la population de l’IRIS dans la population totale (%) -> Population * 100 / Population (total Roubaix) | B5: Densité de logements par hectare -> Logements / Superficie en hectares (LOG) | C5: Part de la population active dans la population en âge de travailler (%) -> Actifs 15-64 ans * 100 / Pop 15-64 ans | D5: Part des familles couple avec enfant(s) (%) -> Fam Couple avec enfant(s) * 100 / Familles | E5: Part pop 15 ans et plus non scol dipl Ens Sup (%) -> Pop 15 ans ou plus non scol dipl Ens Sup * 100 / Pop 15 ans ou plus non scolarisée | F5: Part des DEFM hommes (%) -> DEFM hommes * 100 / Population (DEFM) | G5: Part des allocataires mono-parent (%) -> Allocataires mono-parent * 100 / Nombre total d'allocataires | H5: Part des moins de 18 ans bénéficiaires de la C2S non participative(%) -> Bénéficiaires de la C2S non participative (ex-CMUC) de moins de 18 ans * 100 / Bénéficiaires du régime général de moins de 18 ans (non calculé : variable absente de ce millésime)
A6: Densité d’habitants à l’hectare -> Population / Superficie en hectares (POP) | B6: Part des logements vacants (%) -> Logements vacants * 100 / Logements | C6: Part des actifs 15-24 ans (%) -> Actifs 15-24 ans * 100 / Pop 15-24 ans | D6: Part de familles monoparentales (%) -> Fam Monoparentales * 100 / Familles | F6: Part des DEFM femmes (%) -> DEFM femmes * 100 / Population (DEFM) | G6: Part des allocataires percevant l’APL (%) -> Allocataires percevant l’Aide Personnalisée au Logement (Métropole) * 100 / Nombre total d'allocataires | H6: Part de la population couverte bénéficiaire de la C2S participative (%) -> Population couverte bénéficiaire de la C2S participative (ex-ACS) * 100 / Population couverte bénéficiaire du régime général (non calculé : variable absente de ce millésime)
A7: Population de plus de 60 ans -> Pop 60-74 ans + Pop 75 ans ou plus (non calculé : variable absente de ce millésime) | B7: Part des logements individuels (%) -> Maisons * 100 / Logements | C7: Taux d’emploi des 15-64 ans (%) -> Actifs occupés 15-64 ans * 100 / Pop 15-64 ans | D7: Nombre de familles nombreuses -> Fam 3 enfants moins 25 ans + Fam 4 enfants ou plus moins 25 ans | F7: Part des DEFM catégorie ABC (tenus de faire une recherche d'emploi active) -> DEFM catégories ABC * 100 / DEFM | G7: Part des allocataires percevant l’AAH (%) -> Allocataires percevant l’Allocation Adulte Handicapé * 100 / Nombre total d'allocataires | H7: Part des bénéficiaires de la C2S participative de moins de 18 ans (%) -> Bénéficiaires de la C2S participative (ex-ACS) de moins de 18 ans * 100 / Population couverte bénéficiaire de la C2S participative (ex-ACS) (non calculé : variable absente de ce millésime)
A8: Part de la population de plus de 60 ans (%) parmi la population iris -> Population de plus de 60 ans * 100 / Population (non calculé : variable absente de ce millésime) | B8: Nombre de RP de petite typologie -> Rés princ 1 pièce + Rés princ 2 pièces | C8: Taux d’emploi des 15-24 ans (%) -> Actifs occupés 15-24 ans * 100 / Pop 15-24 ans | D8: Part de familles nombreuses (%) -> Nombre de familles nombreuses * 100 / Familles | F8: Part des DEFM ABC de moins de 26 ans (%) -> DEFM catégories ABC moins de 26 ans * 100 / DEFM catégories ABC | G8: Part des allocataires bénéficiant du RSA socle (%) -> Allocataires percevant le RSA socle * 100 / Nombre total d'allocataires | H8: Part des moins de 18 ans bénéficiaires de la C2S participative (%) -> Bénéficiaires de la C2S participative (ex-ACS) de moins de 18 ans * 100 / Bénéficiaires du régime général de moins de 18 ans (non calculé : variable absente de ce millésime)
A9: Part de la population de moins de 20 ans (%) parmi la population iris -> Pop 0-19 ans * 100 / Population | B9: Part des RP de petite typologie (%) -> Nombre de RP de petite typologie * 100 / Résidences principales | C9: Taux de chômage dans la pop active (%) -> Chômeurs 15-64 ans * 100 / Actifs 15-64 ans | F9: Part des DEFM ABC de niveau ≤ au BAC dans les DEFM ABC (%) -> (DEFM catégories ABC de niveau de formation inférieur au CAP-BEP + DEFM catégories ABC de niveau de formation CAP-BEP + DEFM catégories ABC de niveau de formation BAC) * 100 / DEFM catégories ABC
A10: Indice de jeunesse -> Pop 0-19 ans / (Pop 60-74 ans + Pop 75 ans ou plus) (non calculé : variable absente de ce millésime) | B10: Nombre de RP de grande typologie -> Rés princ 3 pièces + Rés princ 4 pièces + Rés princ 5 pièces ou plus | C10: Taux de chômage chez les 15-24 ans dans la pop active (%) -> Chômeurs 15-24 ans * 100 / Actifs 15-24 ans | F10: Part des DEFM ABC au chômage depuis plus de 2 ans parmi les DEFM ABC (%) -> DEFM catégories ABC d'ancienneté au chômage d'au moins 2 ans * 100 / DEFM catégories ABC
A11: Indice de vieillissement -> Pop 65 ans ou plus / Pop 0-19 ans | B11: Part des RP de grande typologie (%) -> Nombre de RP de grande typologie * 100 / Résidences principales | C11: Part salariés chez les actifs occupés (%) -> Salariés 15 ans ou plus * 100 / Actifs occupés 15 ans ou plus | F11: Part des DEFM ABC au chômage depuis plus de 2 ans dans l'ensemble des chômeurs inscrits à PE (%) -> DEFM catégories ABC d'ancienneté au chômage d'au moins 2 ans * 100 / DEFM
A12: Part de la population étrangère parmi la population iris (%) -> Pop Etrangers * 100 / Population | B12: Part des ménages emménagés depuis moins de 2 ans (%) -> Ménages emménagés moins 2 ans * 100 / Ménages | C12: Part des femmes chez les salariés de 15 ans et plus (%) -> Salariés 15 ans ou plus Femmes * 100 / Salariés 15 ans ou plus | F12: Part des DEFM ABC bénéficiaires du RSA parmi les DEFM ABC (%) -> DEFM catégories ABC bénéficiaires du RSA * 100 / DEFM catégories ABC
A13: Part de la population immigrée parmi la population iris (%) -> Pop Immigrés * 100 / Population | B13: Ménages emménagés moins 10 ans -> Ménages - Ménages emménagés depuis 10 ans ou plus | C13: Part des actifs occupés salariés en CDI ou fonction publique (%) -> Salariés 15 ans ou plus Fonct publ, CDI * 100 / Salariés 15 ans ou plus | F13: Part des DEFM ABC bénéficiaires du RSA parmi l'ensemble des inscrits à PE (%) -> DEFM catégories ABC bénéficiaires du RSA * 100 / DEFM
B14: Part des ménages emménagés depuis moins de 10 ans (%) -> Ménages emménagés moins 10 ans * 100 / Ménages | C14: Part des actifs occupés travaillant dans la commune de résidence (%) -> Actif occ 15 ans ou plus travaille commune résidence * 100 / Actifs occupés 15 ans ou plus
B15: Taille moyenne des ménages -> Pop Ménages / Ménages
B16: Nombre de RP parc privé -> Résidences principales - Rés princ HLM louée vide
B17: Part propriétaire dans les RP parc privé (%) -> Rés princ occupées Propriétaires * 100 / Nombre de RP parc privé
B18: Part propriétaire dans le parc de RP total (%) -> Rés princ occupées Propriétaires * 100 / Résidences principales
B19: Part HLM dans RP totale (%) -> Rés princ HLM louée vide * 100 / Résidences principales
B20: Part HLM dans les RP locataires (%) -> Rés princ HLM louée vide * 100 / Rés princ occupées Locataires
B21: Part des ménages avec parking (%) -> Ménages au moins un parking * 100 / Ménages
B22: Part des ménages avec au moins une voiture (%) -> Ménages au moins une voiture * 100 / Ménages

Sheet POP 2023
A1: Données infra-communales - Population | D1: =SUBTOTAL(9,D3:D40) | E1: =SUBTOTAL(9,E3:E40) | F1: =SUBTOTAL(9,F3:F40) | G1: =SUBTOTAL(9,G3:G40) | H1: =SUBTOTAL(9,H3:H40) | I1: =SUBTOTAL(9,I3:I40) | J1: =SUBTOTAL(9,J3:J40) | K1: =SUBTOTAL(9,K3:K40) | ... BM1: =SUBTOTAL(9,BM3:BM40)
A2: Mairies de quartiers | B2: Grands quartiers | C2: Libellé de l'Iris | D2: Population | E2: Pop 0-2 ans | F2: Pop 3-5 ans | G2: Pop 6-10 ans | H2: Pop 11-17 ans | I2: Pop 18-24 ans | J2: Pop 25-39 ans | K2: Pop 40-54 ans | L2: Pop 55-64 ans | M2: Pop 65-79 ans | N2: Pop 80 ans ou plus | O2: Pop 0-14 ans | P2: Pop 0-19 ans | Q2: Pop 20-64 ans | R2: Pop 65 ans ou plus | S2: Pop Hommes | T2: Pop Hommes 0-14 ans | U2: Pop Hommes 0-19 ans | V2: Pop Hommes 20-64 ans | W2: Pop Hommes 65 ans ou plus | X2: Pop Femmes | Y2: Pop Femmes 0-14 ans | Z2: Pop Femmes 0-19 ans | AA2: Pop Femmes 20-64 ans | AB2: Pop Femmes 65 ans ou plus | AC2: Pop 15 ans ou plus | AD2: Pop 15 ans ou plus Agriculteurs exploitants | AE2: Pop 15 ans ou plus Artisans, Comm., Chefs entr. | AF2: Pop 15 ans ou plus Cadres, Prof. intel. sup. | AG2: Pop 15 ans ou plus Prof. intermédiaires | AH2: Pop 15 ans ou plus Employés | AI2: Pop 15 ans ou plus Ouvriers | AJ2: Pop 15 ans ou plus Retraités | AK2: Pop 15 ans ou plus Autres | AL2: Pop 15 ans ou plus Hommes | AM2: Pop 15 ans ou plus Hommes Agriculteurs exploitants | AN2: Pop 15 ans ou plus Hommes Artisans, Comm., Chefs entr. | AO2: Pop 15 ans ou plus Hommes Cadres, Prof. intel. sup. | AP2: Pop 15 ans ou plus Hommes Prof. intermédiaires | AQ2: Pop 15 ans ou plus Hommes Employés | AR2: Pop 15 ans ou plus Hommes Ouvriers | AS2: Pop 15 ans ou plus Hommes Retraités | AT2: Pop 15 ans ou plus Hommes Autres | AU2: Pop 15 ans ou plus Femmes | AV2: Pop 15 ans ou plus Femmes Agriculteurs exploitants | AW2: Pop 15 ans ou plus Femmes Artisans, Comm., Chefs entr. | AX2: Pop 15 ans ou plus Femmes Cadres, Prof. intel. sup. | AY2: Pop 15 ans ou plus Femmes Prof. intermédiaires | AZ2: Pop 15 ans ou plus Femmes Employés | BA2: Pop 15 ans ou plus Femmes Ouvriers | BB2: Pop 15 ans ou plus Femmes Retraités | BC2: Pop 15 ans ou plus Femmes Autres | BD2: Pop Français | BE2: Pop Etrangers | BF2: Pop Immigrés | BG2: Pop ménages | BH2: Pop hors ménages | BI2: Pop 15-24 ans | BJ2: Pop 15-24 ans Hommes | BK2: Pop 15-24 ans Femmes | BL2: Superficie en km² | BM2: Superficie en hectares (POP) | BN2: Densité de population en hab/km² | BO2: Part de la population de l’IRIS dans la population totale (%) | BP2: Densité d’habitants à l’hectare | BQ2: Part de la population de moins de 20 ans (%) parmi la population iris | BR2: Indice de vieillissement | BS2: Part de la population étrangère parmi la population iris (%) | BT2: Part de la population immigrée parmi la population iris (%)
A3: OUEST | B3: FRESNOY MACKELLERIE | C3: Mackellerie | D3: 2501 | E3: 99 | F3: 204 | G3: 235 | H3: 304 | I3: 256 | J3: 540 | K3: 413 | L3: 221 | M3: 173 | N3: 55 | O3: 725 | P3: 914 | Q3: 1358 | R3: 229 | S3: 1280 | T3: 415 | U3: 519 | V3: 647 | W3: 115 | X3: 1221 | Y3: 310 | Z3: 395 | AA3: 711 | AB3: 114 | AC3: 1849 | AD3: 0 | AE3: 36 | AF3: 87 | AG3: 175 | AH3: 370 | AI3: 334 | AJ3: 283 | AK3: 564 | AL3: 869 | AM3: 0 | AN3: 18 | AO3: 50 | AP3: 91 | AQ3: 121 | AR3: 257 | AS3: 137 | AT3: 193 | AU3: 981 | AV3: 0 | AW3: 18 | AX3: 38 | AY3: 84 | AZ3: 249 | BA3: 76 | BB3: 146 | BC3: 371 | BD3: 2113 | BE3: 388 | BF3: 502 | BG3: 2460 | BH3: 41 | BI3: 373 | BJ3: 166 | BK3: 207 | BL3: 0.32 | BM3: 31.63 | BN3: 7906.73 | BO3: 2.5 | BP3: 79.07 | BQ3: 36.6 | BR3: 0.25 | BS3: 15.5 | BT3: 20.1
A4: OUEST | B4: ARMENTIERES | C4: Fresnoy | D4: 4280 | E4: 112 | F4: 174 | G4: 338 | H4: 447 | I4: 784 | J4: 834 | K4: 781 | L4: 403 | M4: 330 | N4: 77 | O4: 877 | P4: 1313 | Q4: 2560 | R4: 407 | S4: 2144 | T4: 496 | U4: 691 | V4: 1267 | W4: 185 | X4: 2135 | Y4: 381 | Z4: 622 | AA4: 1293 | AB4: 221 | AC4: 3619 | AD4: 0 | AE4: 71 | AF4: 308 | AG4: 441 | AH4: 614 | AI4: 458 | AJ4: 467 | AK4: 1260 | AL4: 1745 | AM4: 0 | AN4: 46 | AO4: 205 | AP4: 225 | AQ4: 244 | AR4: 346 | AS4: 200 | AT4: 479 | AU4: 1875 | AV4: 0 | AW4: 25 | AX4: 104 | AY4: 216 | AZ4: 370 | BA4: 111 | BB4: 268 | BC4: 781 | BD4: 3567 | BE4: 713 | BF4: 892 | BG4: 4279 | BH4: 0 | BI4: 978 | BJ4: 423 | BK4: 555 | BL4: 0.53 | BM4: 52.75 | BN4: 8113.17 | BO4: 4.4 | BP4: 81.13 | BQ4: 30.7 | BR4: 0.31 | BS4: 16.7 | BT4: 20.8
A5: NORD | B5: FOSSE AUX CHENES | C5: Fosse aux Chênes | D5: 2843 | E5: 98 | F5: 189 | G5: 181 | H5: 312 | I5: 332 | J5: 499 | K5: 585 | L5: 276 | M5: 273 | N5: 98 | O5: 653 | P5: 869 | Q5: 1604 | R5: 370 | S5: 1413 | T5: 356 | U5: 456 | V5: 786 | W5: 172 | X5: 1430 | Y5: 296 | Z5: 413 | AA5: 818 | AB5: 199 | AC5: 1948 | AD5: 0 | AE5: 56 | AF5: 52 | AG5: 93 | AH5: 259 | AI5: 307 | AJ5: 403 | AK5: 777 | AL5: 922 | AM5: 0 | AN5: 46 | AO5: 19 | AP5: 38 | AQ5: 54 | AR5: 234 | AS5: 185 | AT5: 346 | AU5: 1026 | AV5: 0 | AW5: 11 | AX5: 33 | AY5: 55 | AZ5: 205 | BA5: 74 | BB5: 218 | BC5: 431 | BD5: 2135 | BE5: 708 | BF5: 834 | BG5: 2703 | BH5: 140 | BI5: 460 | BJ5: 214 | BK5: 246 | BL5: 0.41 | BM5: 40.66 | BN5: 6992.38 | BO5: 2.9 | BP5: 69.93 | BQ5: 30.5 | BR5: 0.43 | BS5: 24.9 | BT5: 29.3
A6: NORD | B6: ALMA GARE | C6: Alma Sud | D6: 1529 | E6: 64 | F6: 124 | G6: 173 | H6: 172 | I6: 217 | J6: 273 | K6: 248 | L6: 161 | M6: 92 | N6: 4 | O6: 452 | P6: 602 | Q6: 830 | R6: 96 | S6: 777 | T6: 245 | U6: 318 | V6: 413 | W6: 47 | X6: 751 | Y6: 207 | Z6: 284 | AA6: 417 | AB6: 49 | AC6: 1051 | AD6: 0 | AE6: 21 | AF6: 15 | AG6: 26 | AH6: 127 | AI6: 237 | AJ6: 111 | AK6: 514 | AL6: 518 | AM6: 0 | AN6: 21 | AO6: 5 | AP6: 15 | AQ6: 32 | AR6: 180 | AS6: 52 | AT6: 212 | AU6: 534 | AV6: 0 | AW6: 0 | AX6: 11 | AY6: 11 | AZ6: 94 | BA6: 58 | BB6: 59 | BC6: 301 | BD6: 974 | BE6: 554 | BF6: 559 | BG6: 1529 | BH6: 0 | BI6: 299 | BJ6: 153 | BK6: 146 | BL6: 0.09 | BM6: 9.35 | BN6: 16355.06 | BO6: 1.6 | BP6: 163.49 | BQ6: 39.4 | BR6: 0.16 | BS6: 36.3 | BT6: 36.6
A7: NORD | B7: ALMA GARE | C7: Alma Nord | D7: 1613 | E7: 45 | F7: 110 | G7: 161 | H7: 248 | I7: 171 | J7: 280 | K7: 300 | L7: 129 | M7: 145 | N7: 25 | O7: 441 | P7: 611 | Q7: 832 | R7: 169 | S7: 799 | T7: 250 | U7: 310 | V7: 399 | W7: 90 | X7: 813 | Y7: 191 | Z7: 301 | AA7: 432 | AB7: 79 | AC7: 1010 | AD7: 0 | AE7: 18 | AF7: 25 | AG7: 60 | AH7: 100 | AI7: 180 | AJ7: 171 | AK7: 456 | AL7: 470 | AM7: 0 | AN7: 18 | AO7: 8 | AP7: 22 | AQ7: 20 | AR7: 137 | AS7: 96 | AT7: 168 | AU7: 540 | AV7: 0 | AW7: 0 | AX7: 17 | AY7: 38 | AZ7: 80 | BA7: 43 | BB7: 75 | BC7: 288 | BD7: 1190 | BE7: 423 | BF7: 503 | BG7: 1613 | BH7: 0 | BI7: 294 | BJ7: 112 | BK7: 182 | BL7: 0.42 | BM7: 41.78 | BN7: 3860.19 | BO7: 1.6 | BP7: 38.6 | BQ7: 37.9 | BR7: 0.28 | BS7: 26.2 | BT7: 31.2
A8: NORD | B8: ENTREPONT | C8: Entrepont-Cartigny | D8: 2372 | E8: 60 | F8: 145 | G8: 231 | H8: 305 | I8: 233 | J8: 427 | K8: 461 | L8: 200 | M8: 260 | N8: 49 | O8: 617 | P8: 834 | Q8: 1229 | R8: 309 | S8: 1190 | T8: 323 | U8: 449 | V8: 593 | W8: 148 | X8: 1182 | Y8: 294 | Z8: 385 | AA8: 636 | AB8: 161 | AC8: 1813 | AD8: 0 | AE8: 40 | AF8: 37 | AG8: 138 | AH8: 299 | AI8: 331 | AJ8: 319 | AK8: 651 | AL8: 899 | AM8: 0 | AN8: 31 | AO8: 12 | AP8: 63 | AQ8: 68 | AR8: 267 | AS8: 162 | AT8: 296 | AU8: 913 | AV8: 0 | AW8: 8 | AX8: 24 | AY8: 75 | AZ8: 231 | BA8: 64 | BB8: 156 | BC8: 355 | BD8: 1783 | BE8: 589 | BF8: 597 | BG8: 2364 | BH8: 8 | BI8: 357 | BJ8: 182 | BK8: 175 | BL8: 0.85 | BM8: 84.99 | BN8: 2790.47 | BO8: 2.4 | BP8: 27.9 | BQ8: 35.2 | BR8: 0.37 | BS8: 24.8 | BT8: 25.2
A9: NORD | B9: HUTIN - ORAN - CARTIGNY | C9: Hutin-Oran | D9: 2166 | E9: 76 | F9: 144 | G9: 166 | H9: 310 | I9: 196 | J9: 351 | K9: 441 | L9: 141 | M9: 269 | N9: 72 | O9: 584 | P9: 768 | Q9: 1057 | R9: 342 | S9: 1041 | T9: 301 | U9: 386 | V9: 510 | W9: 145 | X9: 1126 | Y9: 283 | Z9: 382 | AA9: 547 | AB9: 197 | AC9: 1543 | AD9: 0 | AE9: 11 | AF9: 42 | AG9: 158 | AH9: 190 | AI9: 286 | AJ9: 363 | AK9: 493 | AL9: 725 | AM9: 0 | AN9: 10 | AO9: 7 | AP9: 83 | AQ9: 61 | AR9: 214 | AS9: 161 | AT9: 188 | AU9: 818 | AV9: 0 | AW9: 1 | AX9: 35 | AY9: 75 | AZ9: 129 | BA9: 72 | BB9: 201 | BC9: 305 | BD9: 1734 | BE9: 432 | BF9: 526 | BG9: 2166 | BH9: 0 | BI9: 308 | BJ9: 139 | BK9: 169 | BL9: 0.42 | BM9: 41.76 | BN9: 5187.63 | BO9: 2.2 | BP9: 51.88 | BQ9: 35.4 | BR9: 0.45 | BS9: 19.9 | BT9: 24.3
A10: NORD | B10: CUL DE FOUR | C10: Cul de Four | D10: 3471 | E10: 108 | F10: 274 | G10: 298 | H10: 525 | I10: 429 | J10: 575 | K10: 638 | L10: 294 | M10: 252 | N10: 78 | O10: 991 | P10: 1355 | Q10: 1785 | R10: 331 | S10: 1791 | T10: 536 | U10: 729 | V10: 897 | W10: 165 | X10: 1680 | Y10: 455 | Z10: 626 | AA10: 888 | AB10: 166 | AC10: 2428 | AD10: 0 | AE10: 36 | AF10: 38 | AG10: 134 | AH10: 314 | AI10: 517 | AJ10: 329 | AK10: 1059 | AL10: 1233 | AM10: 0 | AN10: 36 | AO10: 32 | AP10: 53 | AQ10: 122 | AR10: 418 | AS10: 132 | AT10: 440 | AU10: 1195 | AV10: 0 | AW10: 0 | AX10: 6 | AY10: 81 | AZ10: 192 | BA10: 99 | BB10: 198 | BC10: 619 | BD10: 2556 | BE10: 915 | BF10: 945 | BG10: 3471 | BH10: 0 | BI10: 643 | BJ10: 356 | BK10: 287 | BL10: 0.56 | BM10: 56.3 | BN10: 6165.13 | BO10: 3.5 | BP10: 61.65 | BQ10: 39 | BR10: 0.24 | BS10: 26.4 | BT10: 27.2
A11: NORD | B11: HOMMELET | C11: Hommelet Nord | D11: 2308 | E11: 68 | F11: 180 | G11: 219 | H11: 297 | I11: 260 | J11: 453 | K11: 410 | L11: 180 | M11: 228 | N11: 14 | O11: 635 | P11: 851 | Q11: 1215 | R11: 242 | S11: 1130 | T11: 281 | U11: 374 | V11: 636 | W11: 121 | X11: 1177 | Y11: 354 | Z11: 477 | AA11: 579 | AB11: 121 | AC11: 1761 | AD11: 0 | AE11: 42 | AF11: 105 | AG11: 137 | AH11: 196 | AI11: 337 | AJ11: 280 | AK11: 665 | AL11: 885 | AM11: 0 | AN11: 38 | AO11: 54 | AP11: 97 | AQ11: 51 | AR11: 264 | AS11: 138 | AT11: 244 | AU11: 876 | AV11: 0 | AW11: 4 | AX11: 50 | AY11: 40 | AZ11: 145 | BA11: 73 | BB11: 143 | BC11: 420 | BD11: 1735 | BE11: 573 | BF11: 608 | BG11: 2308 | BH11: 0 | BI11: 388 | BJ11: 165 | BK11: 223 | BL11: 0.18 | BM11: 18.34 | BN11: 12585.26 | BO11: 2.3 | BP11: 125.84 | BQ11: 36.9 | BR11: 0.28 | BS11: 24.8 | BT11: 26.3
A12: NORD | B12: HOMMELET | C12: Hommelet Centre | D12: 2774 | E12: 69 | F12: 204 | G12: 247 | H12: 436 | I12: 267 | J12: 363 | K12: 550 | L12: 270 | M12: 262 | N12: 106 | O12: 746 | P12: 1045 | Q12: 1361 | R12: 369 | S12: 1300 | T12: 367 | U12: 540 | V12: 614 | W12: 145 | X12: 1474 | Y12: 378 | Z12: 505 | AA12: 747 | AB12: 223 | AC12: 2141 | AD12: 0 | AE12: 53 | AF12: 45 | AG12: 121 | AH12: 313 | AI12: 374 | AJ12: 405 | AK12: 830 | AL12: 1000 | AM12: 0 | AN12: 36 | AO12: 26 | AP12: 68 | AQ12: 118 | AR12: 267 | AS12: 172 | AT12: 313 | AU12: 1141 | AV12: 0 | AW12: 17 | AX12: 20 | AY12: 53 | AZ12: 195 | BA12: 107 | BB12: 233 | BC12: 517 | BD12: 2086 | BE12: 688 | BF12: 784 | BG12: 2701 | BH12: 73 | BI12: 477 | BJ12: 249 | BK12: 228 | BL12: 0.28 | BM12: 28.27 | BN12: 9811.37 | BO12: 2.8 | BP12: 98.12 | BQ12: 37.7 | BR12: 0.35 | BS12: 24.8 | BT12: 28.3
A13: NORD | B13: HOMMELET | C13: Hommelet Sud | D13: 2353 | E13: 56 | F13: 132 | G13: 197 | H13: 302 | I13: 302 | J13: 428 | K13: 474 | L13: 217 | M13: 182 | N13: 63 | O13: 533 | P13: 777 | Q13: 1332 | R13: 245 | S13: 1229 | T13: 272 | U13: 385 | V13: 728 | W13: 116 | X13: 1124 | Y13: 261 | Z13: 391 | AA13: 604 | AB13: 129 | AC13: 1909 | AD13: 0 | AE13: 38 | AF13: 132 | AG13: 126 | AH13: 273 | AI13: 389 | AJ13: 266 | AK13: 685 | AL13: 986 | AM13: 0 | AN13: 25 | AO13: 85 | AP13: 64 | AQ13: 90 | AR13: 313 | AS13: 125 | AT13: 283 | AU13: 923 | AV13: 0 | AW13: 13 | AX13: 47 | AY13: 61 | AZ13: 182 | BA13: 76 | BB13: 141 | BC13: 402 | BD13: 1736 | BE13: 618 | BF13: 681 | BG13: 2250 | BH13: 103 | BI13: 457 | BJ13: 247 | BK13: 210 | BL13: 0.21 | BM13: 21.15 | BN13: 11129.05 | BO13: 2.4 | BP13: 111.27 | BQ13: 33 | BR13: 0.31 | BS13: 26.2 | BT13: 28.9
A14: OUEST | B14: EPEULE | C14: Épeule Nord | D14: 1947 | E14: 46 | F14: 124 | G14: 198 | H14: 210 | I14: 204 | J14: 313 | K14: 369 | L14: 249 | M14: 194 | N14: 40 | O14: 475 | P14: 660 | Q14: 1054 | R14: 233 | S14: 964 | T14: 230 | U14: 325 | V14: 510 | W14: 129 | X14: 983 | Y14: 245 | Z14: 335 | AA14: 544 | AB14: 104 | AC14: 1347 | AD14: 0 | AE14: 31 | AF14: 15 | AG14: 87 | AH14: 198 | AI14: 256 | AJ14: 214 | AK14: 546 | AL14: 692 | AM14: 0 | AN14: 28 | AO14: 8 | AP14: 35 | AQ14: 80 | AR14: 206 | AS14: 123 | AT14: 212 | AU14: 656 | AV14: 0 | AW14: 3 | AX14: 7 | AY14: 52 | AZ14: 119 | BA14: 50 | BB14: 91 | BC14: 333 | BD14: 1254 | BE14: 694 | BF14: 685 | BG14: 1947 | BH14: 0 | BI14: 308 | BJ14: 158 | BK14: 150 | BL14: 0.15 | BM14: 15.31 | BN14: 12719.86 | BO14: 2 | BP14: 127.18 | BQ14: 33.9 | BR14: 0.35 | BS14: 35.6 | BT14: 35.2
... A40: SUD | B40: HAUTS CHAMPS/PETITES HAIES | C40: Hauts Champs | D40: 2227 | E40: 70 | F40: 156 | G40: 185 | H40: 204 | I40: 289 | J40: 424 | K40: 407 | L40: 227 | M40: 209 | N40: 57 | O40: 535 | P40: 705 | Q40: 1257 | R40: 266 | S40: 1045 | T40: 283 | U40: 361 | V40: 595 | W40: 89 | X40: 1183 | Y40: 252 | Z40: 344 | AA40: 662 | AB40: 177 | AC40: 1649 | AD40: 0 | AE40: 49 | AF40: 21 | AG40: 108 | AH40: 346 | AI40: 347 | AJ40: 312 | AK40: 466 | AL40: 760 | AM40: 0 | AN40: 40 | AO40: 8 | AP40: 35 | AQ40: 124 | AR40: 291 | AS40: 106 | AT40: 157 | AU40: 889 | AV40: 0 | AW40: 10 | AX40: 13 | AY40: 74 | AZ40: 222 | BA40: 56 | BB40: 206 | BC40: 309 | BD40: 1804 | BE40: 423 | BF40: 490 | BG40: 2171 | BH40: 56 | BI40: 368 | BJ40: 195 | BK40: 173 | BL40: 0.31 | BM40: 31.34 | BN40: 7107.07 | BO40: 2.3 | BP40: 71.07 | BQ40: 31.6 | BR40: 0.38 | BS40: 19 | BT40: 22

Sheet ACT RES 2023
A1: Données infra-communales - Activité des résidents | D1: =SUBTOTAL(9,D3:D40) | E1: =SUBTOTAL(9,E3:E40) | F1: =SUBTOTAL(9,F3:F40) | G1: =SUBTOTAL(9,G3:G40) | H1: =SUBTOTAL(9,H3:H40) | I1: =SUBTOTAL(9,I3:I40) | J1: =SUBTOTAL(9,J3:J40) | K1: =SUBTOTAL(9,K3:K40) | ... CJ1: =SUBTOTAL(9,CJ3:CJ40)
A2: Mairies de quartiers | B2: Grands quartiers | C2: Libellé de l'Iris | D2: Pop 15-64 ans | E2: Pop 15-24 ans | F2: Pop 25-54 ans | G2: Pop 55-64 ans | H2: Pop 15-64 ans Hommes | I2: Pop 15-24 ans Hommes | J2: Pop 25-54 ans Hommes | K2: Pop 55-64 ans Hommes | L2: Pop 15-64 ans Femmes | M2: Pop 15-24 ans Femmes | N2: Pop 25-54 ans Femmes | O2: Pop 55-64 ans Femmes | P2: Actifs 15-64 ans | Q2: Actifs 15-24 ans | R2: Actifs 25-54 ans | S2: Actifs 55-64 ans | T2: Actifs 15-64 ans Hommes | U2: Actifs 15-24 ans Hommes | V2: Actifs 25-54 ans Hommes | W2: Actifs 55-64 ans Hommes | X2: Actifs 15-64 ans Femmes | Y2: Actifs 15-24 ans Femmes | Z2: Actifs 25-54 ans Femmes | AA2: Actifs 55-64 ans Femmes | AB2: Actifs occupés 15-64 ans | AC2: Actifs occupés 15-24 ans | AD2: Actifs occupés 25-54 ans | AE2: Actifs occupés 55-64 ans | AF2: Actifs occupés 15-64 ans Hommes | AG2: Actifs occupés 15-24 ans Hommes | AH2: Actifs occupés 25-54 ans Hommes | AI2: Actifs occupés 55-64 ans Hommes | AJ2: Actifs occupés 15-64 ans Femmes | AK2: Actifs occupés 15-24 ans Femmes | AL2: Actifs occupés 25-54 ans Femmes | AM2: Actifs occupés 55-64 ans Femmes | AN2: Chômeurs 15-64 ans | AO2: Chômeurs 15-24 ans | AP2: Chômeurs 25-54 ans | AQ2: Chômeurs 55-64 ans | AR2: Inactifs 15-64 ans | AS2: Elèv. Etud. Stag. non rémunérés 15-64 ans | AT2: Retraités Préretraités 15-64 ans | AU2: Autres inactifs 15-64 ans | AV2: Actifs 15-64 ans Agriculteurs exploitants | AW2: Actifs 15-64 ans Artisans, Comm., Chefs entr. | AX2: Actifs 15-64 ans Cadres, Prof. intel. sup. | AY2: Actifs 15-64 ans Prof. intermédiaires | AZ2: Actifs 15-64 ans Employés | BA2: Actifs 15-64 ans Ouvriers | BB2: Actifs occ 15-64 ans Agriculteurs exploitants | BC2: Actifs occ 15-64 ans Artisans, Comm., Chefs entr. | BD2: Actifs occ 15-64 ans Cadres Prof. intel. sup. | BE2: Actifs occ 15-64 ans Prof. intermédiaires | BF2: Actifs occupés 15-64 ans Employés | BG2: Actifs occupés 15-64 ans Ouvriers | BH2: Actifs occupés 15 ans ou plus | BI2: Actifs occupés 15 ans ou plus Hommes | BJ2: Actifs occupés 15 ans ou plus Femmes | BK2: Salariés 15 ans ou plus | BL2: Salariés 15 ans ou plus Hommes | BM2: Salariés 15 ans ou plus Femmes | BN2: Non-salariés 15 ans ou plus | BO2: Non-salariés 15 ans ou plus Hommes | BP2: Non-salariés 15 ans ou plus Femmes | BQ2: Actifs occ 15 ans ou plus TP | BR2: Salariés 15 ans ou plus TP | BS2: Salariés 15 ans ou plus TP Hommes | BT2: Salariés 15 ans ou plus TP Femmes | BU2: Non-salariés 15 ans ou plus TP | BV2: Salariés 15 ans ou plus Fonct publ, CDI | BW2: Actif occ 15 ans ou plus travaille commune résidence | BX2: Actif occ 15 ans ou plus travaille autre commune que commune résidence | BY2: Actif occ 15 ans ou plus travaille autre commune même dépt résidence | BZ2: Actif occ 15 ans ou plus travaille autre dépt même région résidence | CA2: Actif occ 15 ans ou plus travaille autre région en métropole | CB2: Actif occ 15 ans ou plus travaille autre région hors métropole | CC2: Actifs occ 15 ans ou plus pas de transport pour travail | CD2: Actifs occ 15 ans ou plus marche à pied pour travail | CE2: Actifs occ 15 ans ou plus vélo | CF2: Actifs occ 15 ans ou plus deux-roues motorisé | CG2: Actifs occ 15 ans ou plus voiture | CH2: Actifs occ 15 ans ou plus transport en commun | CI2: Superficie en km² | CJ2: Population (ACT RES) | CK2: Part de la population en âge de travailler (%) | CL2: Part de la population active dans la population en âge de travailler (%) | CM2: Part des actifs 15-24 ans (%) | CN2: Taux d’emploi des 15-64 ans (%) | CO2: Taux d’emploi des 15-24 ans (%) | CP2: Taux de chômage dans la pop active (%) | CQ2: Taux de chômage chez les 15-24 ans dans la pop active (%) | CR2: Part salariés chez les actifs occupés (%) | CS2: Part des femmes chez les salariés de 15 ans et plus (%) | CT2: Part des actifs occupés salariés en CDI ou fonction publique (%) | CU2: Part des actifs occupés travaillant dans la commune de résidence (%)
A3: OUEST | B3: FRESNOY MACKELLERIE | C3: Mackellerie | D3: 1547 | E3: 373 | F3: 953 | G3: 221 | H3: 750 | I3: 166 | J3: 476 | K3: 108 | L3: 796 | M3: 207 | N3: 476 | O3: 113 | P3: 973 | Q3: 156 | R3: 718 | S3: 99 | T3: 507 | U3: 67 | V3: 393 | W3: 47 | X3: 465 | Y3: 89 | Z3: 325 | AA3: 51 | AB3: 686 | AC3: 70 | AD3: 533 | AE3: 83 | AF3: 368 | AG3: 25 | AH3: 308 | AI3: 35 | AJ3: 318 | AK3: 45 | AL3: 225 | AM3: 48 | AN3: 286 | AO3: 86 | AP3: 185 | AQ3: 15 | AR3: 574 | AS3: 215 | AT3: 55 | AU3: 304 | AV3: 0 | AW3: 32 | AX3: 87 | AY3: 171 | AZ3: 366 | BA3: 332 | BB3: 0 | BC3: 24 | BD3: 87 | BE3: 166 | BF3: 259 | BG3: 220 | BH3: 696 | BI3: 375 | BJ3: 322 | BK3: 640 | BL3: 343 | BM3: 297 | BN3: 57 | BO3: 32 | BP3: 25 | BQ3: 133 | BR3: 120 | BS3: 47 | BT3: 73 | BU3: 12 | BV3: 495 | BW3: 217 | BX3: 480 | BY3: 453 | BZ3: 10 | CA3: 7 | CB3: 10 | CC3: 15 | CD3: 62 | CE3: 20 | CF3: 16 | CG3: 383 | CH3: 200 | CI3: 0.32 | CJ3: 2501 | CK3: 61.8 | CL3: 62.9 | CM3: 41.8 | CN3: 44.4 | CO3: 18.6 | CP3: 29.5 | CQ3: 55.4 | CR3: 91.9 | CS3: 46.4 | CT3: 77.5 | CU3: 31.1
A4: OUEST | B4: ARMENTIERES | C4: Fresnoy | D4: 2996 | E4: 978 | F4: 1615 | G4: 403 | H4: 1463 | I4: 423 | J4: 805 | K4: 235 | L4: 1533 | M4: 555 | N4: 811 | O4: 168 | P4: 1866 | Q4: 355 | R4: 1271 | S4: 240 | T4: 1021 | U4: 168 | V4: 689 | W4: 164 | X4: 845 | Y4: 187 | Z4: 582 | AA4: 76 | AB4: 1410 | AC4: 225 | AD4: 996 | AE4: 190 | AF4: 816 | AG4: 122 | AH4: 555 | AI4: 138 | AJ4: 595 | AK4: 102 | AL4: 441 | AM4: 51 | AN4: 456 | AO4: 131 | AP4: 275 | AQ4: 50 | AR4: 1130 | AS4: 573 | AT4: 73 | AU4: 484 | AV4: 0 | AW4: 71 | AX4: 308 | AY4: 432 | AZ4: 595 | BA4: 441 | BB4: 0 | BC4: 64 | BD4: 296 | BE4: 391 | BF4: 454 | BG4: 318 | BH4: 1439 | BI4: 833 | BJ4: 606 | BK4: 1286 | BL4: 733 | BM4: 553 | BN4: 154 | BO4: 100 | BP4: 53 | BQ4: 301 | BR4: 263 | BS4: 95 | BT4: 167 | BU4: 39 | BV4: 951 | BW4: 453 | BX4: 986 | BY4: 861 | BZ4: 26 | CA4: 35 | CB4: 65 | CC4: 27 | CD4: 85 | CE4: 12 | CF4: 15 | CG4: 887 | CH4: 414 | CI4: 0.53 | CJ4: 4280 | CK4: 70 | CL4: 62.3 | CM4: 36.3 | CN4: 47.1 | CO4: 23 | CP4: 24.4 | CQ4: 36.8 | CR4: 89.3 | CS4: 43 | CT4: 74 | CU4: 31.5
A5: NORD | B5: FOSSE AUX CHENES | C5: Fosse aux Chênes | D5: 1820 | E5: 460 | F5: 1084 | G5: 276 | H5: 885 | I5: 214 | J5: 549 | K5: 123 | L5: 935 | M5: 246 | N5: 535 | O5: 153 | P5: 937 | Q5: 143 | R5: 695 | S5: 99 | T5: 507 | U5: 68 | V5: 399 | W5: 40 | X5: 430 | Y5: 75 | Z5: 295 | AA5: 59 | AB5: 662 | AC5: 96 | AD5: 492 | AE5: 73 | AF5: 341 | AG5: 39 | AH5: 273 | AI5: 29 | AJ5: 321 | AK5: 57 | AL5: 219 | AM5: 44 | AN5: 275 | AO5: 47 | AP5: 203 | AQ5: 26 | AR5: 883 | AS5: 286 | AT5: 63 | AU5: 533 | AV5: 0 | AW5: 48 | AX5: 52 | AY5: 93 | AZ5: 255 | BA5: 303 | BB5: 0 | BC5: 48 | BD5: 48 | BE5: 83 | BF5: 205 | BG5: 209 | BH5: 678 | BI5: 352 | BJ5: 325 | BK5: 584 | BL5: 298 | BM5: 286 | BN5: 94 | BO5: 54 | BP5: 39 | BQ5: 192 | BR5: 161 | BS5: 56 | BT5: 105 | BU5: 31 | BV5: 369 | BW5: 318 | BX5: 359 | BY5: 308 | BZ5: 6 | CA5: 21 | CB5: 24 | CC5: 35 | CD5: 135 | CE5: 9 | CF5: 0 | CG5: 284 | CH5: 215 | CI5: 0.41 | CJ5: 2843 | CK5: 64 | CL5: 51.5 | CM5: 31.2 | CN5: 36.4 | CO5: 21 | CP5: 29.4 | CQ5: 32.7 | CR5: 86.2 | CS5: 48.9 | CT5: 63.2 | CU5: 47
A6: NORD | B6: ALMA GARE | C6: Alma Sud | D6: 981 | E6: 299 | F6: 522 | G6: 161 | H6: 486 | I6: 153 | J6: 239 | K6: 94 | L6: 495 | M6: 146 | N6: 282 | O6: 67 | P6: 487 | Q6: 77 | R6: 331 | S6: 78 | T6: 268 | U6: 39 | V6: 180 | W6: 50 | X6: 219 | Y6: 39 | Z6: 151 | AA6: 29 | AB6: 267 | AC6: 26 | AD6: 187 | AE6: 54 | AF6: 155 | AG6: 18 | AH6: 113 | AI6: 25 | AJ6: 112 | AK6: 9 | AL6: 74 | AM6: 29 | AN6: 220 | AO6: 51 | AP6: 144 | AQ6: 25 | AR6: 494 | AS6: 179 | AT6: 17 | AU6: 298 | AV6: 0 | AW6: 21 | AX6: 15 | AY6: 26 | AZ6: 127 | BA6: 237 | BB6: 0 | BC6: 16 | BD6: 0 | BE6: 21 | BF6: 99 | BG6: 143 | BH6: 267 | BI6: 155 | BJ6: 112 | BK6: 250 | BL6: 139 | BM6: 112 | BN6: 17 | BO6: 17 | BP6: 0 | BQ6: 66 | BR6: 62 | BS6: 24 | BT6: 38 | BU6: 4 | BV6: 175 | BW6: 101 | BX6: 166 | BY6: 137 | BZ6: 4 | CA6: 0 | CB6: 25 | CC6: 8 | CD6: 29 | CE6: 5 | CF6: 0 | CG6: 142 | CH6: 82 | CI6: 0.09 | CJ6: 1529 | CK6: 64.2 | CL6: 49.7 | CM6: 25.9 | CN6: 27.2 | CO6: 8.8 | CP6: 45.2 | CQ6: 66.2 | CR6: 93.7 | CS6: 44.7 | CT6: 69.8 | CU6: 37.8
A7: NORD | B7: ALMA GARE | C7: Alma Nord | D7: 1003 | E7: 294 | F7: 580 | G7: 129 | H7: 459 | I7: 112 | J7: 276 | K7: 71 | L7: 543 | M7: 182 | N7: 304 | O7: 58 | P7: 493 | Q7: 80 | R7: 351 | S7: 63 | T7: 298 | U7: 40 | V7: 218 | W7: 40 | X7: 196 | Y7: 40 | Z7: 132 | AA7: 23 | AB7: 357 | AC7: 57 | AD7: 254 | AE7: 46 | AF7: 201 | AG7: 23 | AH7: 152 | AI7: 26 | AJ7: 155 | AK7: 34 | AL7: 102 | AM7: 20 | AN7: 136 | AO7: 23 | AP7: 96 | AQ7: 17 | AR7: 509 | AS7: 166 | AT7: 21 | AU7: 323 | AV7: 0 | AW7: 18 | AX7: 25 | AY7: 52 | AZ7: 83 | BA7: 176 | BB7: 0 | BC7: 16 | BD7: 20 | BE7: 48 | BF7: 75 | BG7: 118 | BH7: 377 | BI7: 208 | BJ7: 169 | BK7: 345 | BL7: 190 | BM7: 155 | BN7: 32 | BO7: 18 | BP7: 14 | BQ7: 86 | BR7: 76 | BS7: 31 | BT7: 44 | BU7: 10 | BV7: 277 | BW7: 157 | BX7: 220 | BY7: 182 | BZ7: 0 | CA7: 6 | CB7: 31 | CC7: 4 | CD7: 41 | CE7: 3 | CF7: 10 | CG7: 218 | CH7: 101 | CI7: 0.42 | CJ7: 1613 | CK7: 62.2 | CL7: 49.2 | CM7: 27.1 | CN7: 35.6 | CO7: 19.3 | CP7: 27.6 | CQ7: 28.8 | CR7: 91.6 | CS7: 44.9 | CT7: 80.2 | CU7: 41.7
A8: NORD | B8: ENTREPONT | C8: Entrepont-Cartigny | D8: 1445 | E8: 357 | F8: 888 | G8: 200 | H8: 719 | I8: 182 | J8: 425 | K8: 112 | L8: 727 | M8: 175 | N8: 463 | O8: 88 | P8: 869 | Q8: 107 | R8: 678 | S8: 84 | T8: 463 | U8: 56 | V8: 362 | W8: 45 | X8: 406 | Y8: 51 | Z8: 316 | AA8: 39 | AB8: 585 | AC8: 61 | AD8: 472 | AE8: 52 | AF8: 320 | AG8: 24 | AH8: 276 | AI8: 20 | AJ8: 266 | AK8: 38 | AL8: 197 | AM8: 31 | AN8: 283 | AO8: 46 | AP8: 205 | AQ8: 32 | AR8: 576 | AS8: 213 | AT8: 33 | AU8: 331 | AV8: 0 | AW8: 36 | AX8: 37 | AY8: 138 | AZ8: 295 | BA8: 327 | BB8: 0 | BC8: 36 | BD8: 31 | BE8: 128 | BF8: 159 | BG8: 220 | BH8: 592 | BI8: 323 | BJ8: 269 | BK8: 527 | BL8: 281 | BM8: 246 | BN8: 65 | BO8: 42 | BP8: 23 | BQ8: 121 | BR8: 100 | BS8: 37 | BT8: 63 | BU8: 21 | BV8: 398 | BW8: 224 | BX8: 367 | BY8: 298 | BZ8: 3 | CA8: 21 | CB8: 44 | CC8: 14 | CD8: 57 | CE8: 6 | CF8: 9 | CG8: 425 | CH8: 80 | CI8: 0.85 | CJ8: 2372 | CK8: 60.9 | CL8: 60.1 | CM8: 30 | CN8: 40.5 | CO8: 17.1 | CP8: 32.6 | CQ8: 42.8 | CR8: 89.1 | CS8: 46.7 | CT8: 75.6 | CU8: 37.9
A9: NORD | B9: HUTIN - ORAN - CARTIGNY | C9: Hutin-Oran | D9: 1240 | E9: 308 | F9: 792 | G9: 141 | H9: 594 | I9: 139 | J9: 374 | K9: 81 | L9: 646 | M9: 169 | N9: 417 | O9: 60 | P9: 769 | Q9: 93 | R9: 585 | S9: 91 | T9: 422 | U9: 44 | V9: 326 | W9: 53 | X9: 346 | Y9: 49 | Z9: 259 | AA9: 38 | AB9: 531 | AC9: 53 | AD9: 421 | AE9: 58 | AF9: 304 | AG9: 27 | AH9: 240 | AI9: 36 | AJ9: 228 | AK9: 26 | AL9: 180 | AM9: 22 | AN9: 237 | AO9: 40 | AP9: 165 | AQ9: 33 | AR9: 471 | AS9: 158 | AT9: 22 | AU9: 291 | AV9: 0 | AW9: 11 | AX9: 42 | AY9: 157 | AZ9: 186 | BA9: 282 | BB9: 0 | BC9: 6 | BD9: 42 | BE9: 141 | BF9: 120 | BG9: 177 | BH9: 548 | BI9: 308 | BJ9: 240 | BK9: 501 | BL9: 279 | BM9: 221 | BN9: 47 | BO9: 29 | BP9: 19 | BQ9: 104 | BR9: 98 | BS9: 46 | BT9: 52 | BU9: 7 | BV9: 372 | BW9: 204 | BX9: 344 | BY9: 291 | BZ9: 4 | CA9: 4 | CB9: 45 | CC9: 16 | CD9: 27 | CE9: 15 | CF9: 3 | CG9: 423 | CH9: 63 | CI9: 0.42 | CJ9: 2166 | CK9: 57.2 | CL9: 62 | CM9: 30 | CN9: 42.8 | CO9: 17.1 | CP9: 30.9 | CQ9: 43.2 | CR9: 91.4 | CS9: 44.2 | CT9: 74.3 | CU9: 37.2
A10: NORD | B10: CUL DE FOUR | C10: Cul de Four | D10: 2149 | E10: 643 | F10: 1213 | G10: 294 | H10: 1090 | I10: 356 | J10: 601 | K10: 133 | L10: 1059 | M10: 287 | N10: 611 | O10: 161 | P10: 1122 | Q10: 195 | R10: 803 | S10: 125 | T10: 701 | U10: 131 | V10: 492 | W10: 78 | X10: 421 | Y10: 63 | Z10: 311 | AA10: 47 | AB10: 687 | AC10: 122 | AD10: 477 | AE10: 89 | AF10: 440 | AG10: 85 | AH10: 301 | AI10: 54 | AJ10: 247 | AK10: 36 | AL10: 176 | AM10: 34 | AN10: 435 | AO10: 73 | AP10: 326 | AQ10: 36 | AR10: 1027 | AS10: 376 | AT10: 48 | AU10: 603 | AV10: 0 | AW10: 32 | AX10: 38 | AY10: 134 | AZ10: 309 | BA10: 508 | BB10: 0 | BC10: 22 | BD10: 38 | BE10: 101 | BF10: 188 | BG10: 325 | BH10: 702 | BI10: 452 | BJ10: 250 | BK10: 678 | BL10: 429 | BM10: 249 | BN10: 24 | BO10: 23 | BP10: 1 | BQ10: 204 | BR10: 200 | BS10: 106 | BT10: 94 | BU10: 4 | BV10: 451 | BW10: 245 | BX10: 457 | BY10: 394 | BZ10: 4 | CA10: 20 | CB10: 39 | CC10: 4 | CD10: 24 | CE10: 55 | CF10: 11 | CG10: 461 | CH10: 146 | CI10: 0.56 | CJ10: 3471 | CK10: 61.9 | CL10: 52.2 | CM10: 30.3 | CN10: 32 | CO10: 18.9 | CP10: 38.8 | CQ10: 37.5 | CR10: 96.6 | CS10: 36.7 | CT10: 66.5 | CU10: 34.9
A11: NORD | B11: HOMMELET | C11: Hommelet Nord | D11: 1431 | E11: 388 | F11: 863 | G11: 180 | H11: 729 | I11: 165 | J11: 459 | K11: 105 | L11: 702 | M11: 223 | N11: 404 | O11: 75 | P11: 829 | Q11: 112 | R11: 624 | S11: 93 | T11: 497 | U11: 45 | V11: 383 | W11: 70 | X11: 332 | Y11: 67 | Z11: 241 | AA11: 24 | AB11: 614 | AC11: 61 | AD11: 480 | AE11: 73 | AF11: 381 | AG11: 25 | AH11: 300 | AI11: 56 | AJ11: 233 | AK11: 37 | AL11: 180 | AM11: 17 | AN11: 216 | AO11: 51 | AP11: 144 | AQ11: 21 | AR11: 602 | AS11: 217 | AT11: 48 | AU11: 336 | AV11: 0 | AW11: 42 | AX11: 105 | AY11: 132 | AZ11: 196 | BA11: 337 | BB11: 0 | BC11: 37 | BD11: 105 | BE11: 98 | BF11: 147 | BG11: 246 | BH11: 617 | BI11: 384 | BJ11: 233 | BK11: 539 | BL11: 326 | BM11: 213 | BN11: 78 | BO11: 58 | BP11: 20 | BQ11: 154 | BR11: 141 | BS11: 45 | BT11: 96 | BU11: 13 | BV11: 423 | BW11: 190 | BX11: 427 | BY11: 373 | BZ11: 10 | CA11: 15 | CB11: 29 | CC11: 32 | CD11: 38 | CE11: 17 | CF11: 0 | CG11: 389 | CH11: 142 | CI11: 0.18 | CJ11: 2308 | CK11: 62 | CL11: 58 | CM11: 28.8 | CN11: 42.9 | CO11: 15.7 | CP11: 26 | CQ11: 45.5 | CR11: 87.3 | CS11: 39.5 | CT11: 78.5 | CU11: 30.8
A12: NORD | B12: HOMMELET | C12: Hommelet Centre | D12: 1660 | E12: 477 | F12: 913 | G12: 270 | H12: 787 | I12: 249 | J12: 394 | K12: 145 | L12: 873 | M12: 228 | N12: 520 | O12: 126 | P12: 916 | Q12: 125 | R12: 656 | S12: 135 | T12: 505 | U12: 77 | V12: 339 | W12: 89 | X12: 412 | Y12: 49 | Z12: 317 | AA12: 47 | AB12: 630 | AC12: 59 | AD12: 468 | AE12: 103 | AF12: 362 | AG12: 32 | AH12: 262 | AI12: 68 | AJ12: 268 | AK12: 27 | AL12: 206 | AM12: 35 | AN12: 287 | AO12: 66 | AP12: 188 | AQ12: 32 | AR12: 743 | AS12: 298 | AT12: 45 | AU12: 401 | AV12: 0 | AW12: 53 | AX12: 39 | AY12: 121 | AZ12: 306 | BA12: 368 | BB12: 0 | BC12: 47 | BD12: 32 | BE12: 100 | BF12: 226 | BG12: 266 | BH12: 641 | BI12: 371 | BJ12: 270 | BK12: 587 | BL12: 336 | BM12: 251 | BN12: 54 | BO12: 34 | BP12: 20 | BQ12: 161 | BR12: 144 | BS12: 63 | BT12: 82 | BU12: 17 | BV12: 425 | BW12: 223 | BX12: 418 | BY12: 371 | BZ12: 3 | CA12: 8 | CB12: 37 | CC12: 10 | CD12: 67 | CE12: 6 | CF12: 3 | CG12: 379 | CH12: 177 | CI12: 0.28 | CJ12: 2774 | CK12: 59.8 | CL12: 55.2 | CM12: 26.3 | CN12: 38 | CO12: 12.4 | CP12: 31.3 | CQ12: 53 | CR12: 91.6 | CS12: 42.7 | CT12: 72.4 | CU12: 34.8
A13: NORD | B13: HOMMELET | C13: Hommelet Sud | D13: 1576 | E13: 457 | F13: 902 | G13: 217 | H13: 842 | I13: 247 | J13: 487 | K13: 108 | L13: 734 | M13: 210 | N13: 416 | O13: 109 | P13: 949 | Q13: 125 | R13: 680 | S13: 144 | T13: 562 | U13: 75 | V13: 402 | W13: 85 | X13: 387 | Y13: 50 | Z13: 278 | AA13: 59 | AB13: 670 | AC13: 75 | AD13: 490 | AE13: 105 | AF13: 415 | AG13: 48 | AH13: 295 | AI13: 72 | AJ13: 255 | AK13: 27 | AL13: 195 | AM13: 33 | AN13: 279 | AO13: 50 | AP13: 190 | AQ13: 39 | AR13: 627 | AS13: 284 | AT13: 30 | AU13: 313 | AV13: 0 | AW13: 38 | AX13: 132 | AY13: 126 | AZ13: 270 | BA13: 384 | BB13: 0 | BC13: 34 | BD13: 123 | BE13: 117 | BF13: 193 | BG13: 258 | BH13: 674 | BI13: 419 | BJ13: 255 | BK13: 600 | BL13: 364 | BM13: 236 | BN13: 74 | BO13: 55 | BP13: 19 | BQ13: 146 | BR13: 137 | BS13: 61 | BT13: 76 | BU13: 9 | BV13: 440 | BW13: 238 | BX13: 436 | BY13: 393 | BZ13: 11 | CA13: 14 | CB13: 18 | CC13: 25 | CD13: 69 | CE13: 12 | CF13: 16 | CG13: 356 | CH13: 195 | CI13: 0.21 | CJ13: 2353 | CK13: 67 | CL13: 60.2 | CM13: 27.4 | CN13: 42.5 | CO13: 16.5 | CP13: 29.4 | CQ13: 39.8 | CR13: 89 | CS13: 39.4 | CT13: 73.3 | CU13: 35.3
A14: OUEST | B14: EPEULE | C14: Épeule Nord | D14: 1239 | E14: 308 | F14: 681 | G14: 249 | H14: 605 | I14: 158 | J14: 340 | K14: 106 | L14: 634 | M14: 150 | N14: 341 | O14: 143 | P14: 681 | Q14: 90 | R14: 452 | S14: 139 | T14: 383 | U14: 47 | V14: 271 | W14: 66 | X14: 298 | Y14: 43 | Z14: 182 | AA14: 73 | AB14: 448 | AC14: 51 | AD14: 294 | AE14: 103 | AF14: 262 | AG14: 21 | AH14: 191 | AI14: 50 | AJ14: 187 | AK14: 30 | AL14: 103 | AM14: 54 | AN14: 232 | AO14: 39 | AP14: 158 | AQ14: 36 | AR14: 558 | AS14: 154 | AT14: 38 | AU14: 366 | AV14: 0 | AW14: 31 | AX14: 15 | AY14: 83 | AZ14: 184 | BA14: 253 | BB14: 0 | BC14: 24 | BD14: 15 | BE14: 62 | BF14: 146 | BG14: 184 | BH14: 466 | BI14: 271 | BJ14: 195 | BK14: 406 | BL14: 233 | BM14: 173 | BN14: 60 | BO14: 38 | BP14: 22 | BQ14: 157 | BR14: 140 | BS14: 64 | BT14: 76 | BU14: 17 | BV14: 276 | BW14: 230 | BX14: 237 | BY14: 202 | BZ14: 8 | CA14: 11 | CB14: 15 | CC14: 27 | CD14: 54 | CE14: 4 | CF14: 3 | CG14: 192 | CH14: 187 | CI14: 0.15 | CJ14: 1947 | CK14: 63.6 | CL14: 55 | CM14: 29.1 | CN14: 36.2 | CO14: 16.6 | CP14: 34.1 | CQ14: 43 | CR14: 87.1 | CS14: 42.7 | CT14: 67.9 | CU14: 49.3
... A40: SUD | B40: HAUTS CHAMPS/PETITES HAIES | C40: Hauts Champs | D40: 1426 | E40: 368 | F40: 831 | G40: 227 | H40: 673 | I40: 195 | J40: 384 | K40: 94 | L40: 753 | M40: 173 | N40: 448 | O40: 133 | P40: 855 | Q40: 165 | R40: 595 | S40: 96 | T40: 493 | U40: 110 | V40: 338 | W40: 45 | X40: 362 | Y40: 55 | Z40: 257 | AA40: 50 | AB40: 557 | AC40: 118 | AD40: 372 | AE40: 67 | AF40: 308 | AG40: 71 | AH40: 211 | AI40: 26 | AJ40: 249 | AK40: 47 | AL40: 161 | AM40: 41 | AN40: 299 | AO40: 47 | AP40: 223 | AQ40: 29 | AR40: 571 | AS40: 149 | AT40: 46 | AU40: 376 | AV40: 0 | AW40: 49 | AX40: 21 | AY40: 108 | AZ40: 343 | BA40: 347 | BB40: 0 | BC40: 42 | BD40: 19 | BE40: 93 | BF40: 251 | BG40: 186 | BH40: 563 | BI40: 312 | BJ40: 252 | BK40: 502 | BL40: 270 | BM40: 232 | BN40: 61 | BO40: 42 | BP40: 20 | BQ40: 108 | BR40: 79 | BS40: 21 | BT40: 58 | BU40: 29 | BV40: 386 | BW40: 244 | BX40: 319 | BY40: 288 | BZ40: 8 | CA40: 12 | CB40: 11 | CC40: 6 | CD40: 38 | CE40: 11 | CF40: 2 | CG40: 370 | CH40: 136 | CI40: 0.31 | CJ40: 2227 | CK40: 64 | CL40: 60 | CM40: 44.7 | CN40: 39 | CO40: 32.1 | CP40: 34.9 | CQ40: 28.3 | CR40: 89.1 | CS40: 46.2 | CT40: 76.9 | CU40: 43.3

Sheet COU FAM 2023
A1: Données infra-communales - Couples - Familles - Ménages | D1: =SUBTOTAL(9,D3:D40) | E1: =SUBTOTAL(9,E3:E40) | F1: =SUBTOTAL(9,F3:F40) | G1: =SUBTOTAL(9,G3:G40) | H1: =SUBTOTAL(9,H3:H40) | I1: =SUBTOTAL(9,I3:I40) | J1: =SUBTOTAL(9,J3:J40) | K1: =SUBTOTAL(9,K3:K40) | ... BC1: =SUBTOTAL(9,BC3:BC40) | BH1: =SUBTOTAL(9,BH3:BH40)
A2: Mairies de quartiers | B2: Grands quartiers | C2: Libellé de l'Iris | D2: Ménages | E2: Ménages 1 personne | F2: Ménages Hommes seuls | G2: Ménages Femmes seules | H2: Ménages Autres sans famille | I2: Ménages avec famille(s) | J2: Mén fam princ Couple sans enfant | K2: Mén fam princ Couple avec enfant(s) | L2: Mén fam princ Famille mono | M2: Pop Ménages | N2: Pop mén Personnes seules | O2: Pop mén Hommes seuls | P2: Pop mén Femmes seules | Q2: Pop mén Autres sans famille | R2: Pop mén avec famille(s) | S2: Pop mén fam princ Couple sans enfant | T2: Pop mén fam princ Couple avec enfant(s) | U2: Pop mén fam princ Famille mono | V2: Pop 15 ans ou plus mariée | W2: Pop 15 ans ou plus pacsée | X2: Pop 15 ans ou plus en concubinage ou union libre | Y2: Pop 15 ans ou plus veuves ou veufs | Z2: Pop 15 ans ou plus divorcée | AA2: Pop 15 ans ou plus célibataire | AB2: Ménages Pers Réf Agri. expl. | AC2: Ménages Pers Réf Art. Comm. Chef entr. | AD2: Ménages Pers Réf Cadre Prof int sup | AE2: Ménages Pers Réf Prof intermédiaire | AF2: Ménages Pers Réf Employé | AG2: Ménages Pers Réf Ouvrier | AH2: Ménages Pers Réf Retraité | AI2: Ménages Pers Réf Autre | AJ2: Pop mén Pers Réf Agri. expl. | AK2: Pop mén Pers Réf Art Com Chef entr. | AL2: Pop mén Pers Réf Cadre Prof int sup | AM2: Pop mén Pers Réf Prof intermédiaire | AN2: Pop mén Pers Réf Employé | AO2: Pop mén Pers Réf Ouvrier | AP2: Pop mén Pers Réf Retraité | AQ2: Pop mén Pers Réf Autre | AR2: Familles | AS2: Fam Couple avec enfant(s) | AT2: Fam Monoparentales | AU2: Fam Couple sans enfant | AV2: Fam 0 enfant moins 25 ans | AW2: Fam 1 enfant moins 25 ans | AX2: Fam 2 enfants moins 25 ans | AY2: Fam 3 enfants moins 25 ans | AZ2: Fam 4 enfants ou plus moins 25 ans | BA2: Fam Couple avec uniq enfant(s) Couple | BB2: Fam Couple avec mini 1 enfant 1 des 2 Couple | BC2: Superficie en km² | BD2: Part des ménages avec famille(s) (%) | BE2: Part des ménages famille couple avec enfant(s) (%) | BF2: Part des familles couple avec enfant(s) (%) | BG2: Part de familles monoparentales (%) | BH2: Nombre de familles nombreuses | BI2: Part de familles nombreuses (%)
A3: OUEST | B3: FRESNOY MACKELLERIE | C3: Mackellerie | D3: 924 | E3: 310 | F3: 191 | G3: 152 | H3: 22 | I3: 617 | J3: 127 | K3: 263 | L3: 227 | M3: 2550 | N3: 342 | O3: 191 | P3: 152 | Q3: 55 | R3: 2153 | S3: 255 | T3: 1189 | U3: 709 | V3: 587 | W3: 31 | X3: 180 | Y3: 90 | Z3: 178 | AA3: 709 | AB3: 0 | AC3: 25 | AD3: 58 | AE3: 124 | AF3: 212 | AG3: 254 | AH3: 154 | AI3: 154 | AJ3: 0 | AK3: 61 | AL3: 187 | AM3: 322 | AN3: 593 | AO3: 772 | AP3: 226 | AQ3: 390 | AR3: 633 | AS3: 263 | AT3: 243 | AU3: 127 | AV3: 193 | AW3: 168 | AX3: 129 | AY3: 70 | AZ3: 73 | BA3: 234 | BB3: 30 | BC3: 0.32 | BD3: 66.8 | BE3: 28.5 | BF3: 41.6 | BG3: 38.3 | BH3: 143 | BI3: 22.6
A4: OUEST | B4: ARMENTIERES | C4: Fresnoy | D4: 1906 | E4: 915 | F4: 516 | G4: 516 | H4: 57 | I4: 978 | J4: 258 | K4: 424 | L4: 296 | M4: 4498 | N4: 1032 | O4: 516 | P4: 516 | Q4: 151 | R4: 3315 | S4: 573 | T4: 1809 | U4: 933 | V4: 1016 | W4: 46 | X4: 384 | Y4: 142 | Z4: 195 | AA4: 1619 | AB4: 0 | AC4: 62 | AD4: 206 | AE4: 267 | AF4: 407 | AG4: 300 | AH4: 293 | AI4: 532 | AJ4: 0 | AK4: 223 | AL4: 491 | AM4: 577 | AN4: 1031 | AO4: 835 | AP4: 487 | AQ4: 853 | AR4: 1000 | AS4: 424 | AT4: 310 | AU4: 267 | AV4: 373 | AW4: 228 | AX4: 198 | AY4: 117 | AZ4: 86 | BA4: 359 | BB4: 65 | BC4: 0.53 | BD4: 51.3 | BE4: 22.2 | BF4: 42.4 | BG4: 30.9 | BH4: 202 | BI4: 20.2
A5: NORD | B5: FOSSE AUX CHENES | C5: Fosse aux Chênes | D5: 1129 | E5: 487 | F5: 245 | G5: 173 | H5: 8 | I5: 561 | J5: 124 | K5: 238 | L5: 199 | M5: 2378 | N5: 418 | O5: 245 | P5: 173 | Q5: 28 | R5: 1931 | S5: 274 | T5: 1092 | U5: 566 | V5: 788 | W5: 14 | X5: 91 | Y5: 125 | Z5: 200 | AA5: 973 | AB5: 0 | AC5: 42 | AD5: 44 | AE5: 53 | AF5: 159 | AG5: 236 | AH5: 198 | AI5: 256 | AJ5: 0 | AK5: 154 | AL5: 103 | AM5: 164 | AN5: 426 | AO5: 694 | AP5: 345 | AQ5: 493 | AR5: 566 | AS5: 238 | AT5: 204 | AU5: 124 | AV5: 197 | AW5: 122 | AX5: 111 | AY5: 88 | AZ5: 49 | BA5: 196 | BB5: 42 | BC5: 0.41 | BD5: 49.7 | BE5: 21.1 | BF5: 42 | BG5: 36 | BH5: 136 | BI5: 24.1
A6: NORD | B6: ALMA GARE | C6: Alma Sud | D6: 493 | E6: 175 | F6: 116 | G6: 69 | H6: 5 | I6: 303 | J6: 27 | K6: 198 | L6: 78 | M6: 1477 | N6: 185 | O6: 116 | P6: 69 | Q6: 11 | R6: 1282 | S6: 53 | T6: 978 | U6: 250 | V6: 432 | W6: 0 | X6: 43 | Y6: 50 | Z6: 83 | AA6: 469 | AB6: 0 | AC6: 21 | AD6: 5 | AE6: 16 | AF6: 63 | AG6: 185 | AH6: 90 | AI6: 113 | AJ6: 0 | AK6: 43 | AL6: 15 | AM6: 31 | AN6: 269 | AO6: 625 | AP6: 190 | AQ6: 305 | AR6: 303 | AS6: 198 | AT6: 78 | AU6: 27 | AV6: 47 | AW6: 69 | AX6: 68 | AY6: 54 | AZ6: 65 | BA6: 172 | BB6: 26 | BC6: 0.09 | BD6: 61.5 | BE6: 40.3 | BF6: 65.4 | BG6: 25.8 | BH6: 119 | BI6: 39.2
A7: NORD | B7: ALMA GARE | C7: Alma Nord | D7: 558 | E7: 178 | F7: 123 | G7: 59 | H7: 9 | I7: 293 | J7: 57 | K7: 151 | L7: 85 | M7: 1321 | N7: 182 | O7: 123 | P7: 59 | Q7: 19 | R7: 1120 | S7: 123 | T7: 737 | U7: 261 | V7: 449 | W7: 7 | X7: 75 | Y7: 64 | Z7: 73 | AA7: 504 | AB7: 0 | AC7: 13 | AD7: 17 | AE7: 39 | AF7: 67 | AG7: 158 | AH7: 96 | AI7: 95 | AJ7: 0 | AK7: 63 | AL7: 58 | AM7: 104 | AN7: 142 | AO7: 510 | AP7: 154 | AQ7: 289 | AR7: 302 | AS7: 150 | AT7: 94 | AU7: 57 | AV7: 91 | AW7: 50 | AX7: 55 | AY7: 53 | AZ7: 53 | BA7: 136 | BB7: 14 | BC7: 0.42 | BD7: 52.5 | BE7: 26.9 | BF7: 49.9 | BG7: 31.2 | BH7: 106 | BI7: 35.1
A8: NORD | B8: ENTREPONT | C8: Entrepont-Cartigny | D8: 892 | E8: 316 | F8: 245 | G8: 107 | H8: 10 | I8: 571 | J8: 105 | K8: 263 | L8: 204 | M8: 2425 | N8: 352 | O8: 245 | P8: 107 | Q8: 20 | R8: 2053 | S8: 214 | T8: 1220 | U8: 619 | V8: 702 | W8: 10 | X8: 119 | Y8: 75 | Z8: 93 | AA8: 755 | AB8: 0 | AC8: 22 | AD8: 20 | AE8: 84 | AF8: 184 | AG8: 250 | AH8: 162 | AI8: 211 | AJ8: 0 | AK8: 82 | AL8: 57 | AM8: 188 | AN8: 576 | AO8: 820 | AP8: 308 | AQ8: 393 | AR8: 581 | AS8: 263 | AT8: 213 | AU8: 105 | AV8: 184 | AW8: 136 | AX8: 116 | AY8: 78 | AZ8: 66 | BA8: 228 | BB8: 35 | BC8: 0.85 | BD8: 64.1 | BE8: 29.5 | BF8: 45.3 | BG8: 36.7 | BH8: 145 | BI8: 24.9
A9: NORD | B9: HUTIN - ORAN - CARTIGNY | C9: Hutin-Oran | D9: 807 | E9: 270 | F9: 138 | G9: 142 | H9: 4 | I9: 507 | J9: 152 | K9: 200 | L9: 155 | M9: 2071 | N9: 280 | O9: 138 | P9: 142 | Q9: 8 | R9: 1783 | S9: 315 | T9: 972 | U9: 496 | V9: 727 | W9: 0 | X9: 67 | Y9: 87 | Z9: 118 | AA9: 584 | AB9: 0 | AC9: 11 | AD9: 31 | AE9: 99 | AF9: 132 | AG9: 209 | AH9: 233 | AI9: 77 | AJ9: 0 | AK9: 58 | AL9: 65 | AM9: 337 | AN9: 375 | AO9: 646 | AP9: 370 | AQ9: 221 | AR9: 514 | AS9: 200 | AT9: 162 | AU9: 152 | AV9: 206 | AW9: 70 | AX9: 112 | AY9: 68 | AZ9: 59 | BA9: 168 | BB9: 32 | BC9: 0.42 | BD9: 62.8 | BE9: 24.8 | BF9: 38.9 | BG9: 31.5 | BH9: 127 | BI9: 24.7
A10: NORD | B10: CUL DE FOUR | C10: Cul de Four | D10: 1059 | E10: 274 | F10: 136 | G10: 137 | H10: 29 | I10: 734 | J10: 155 | K10: 363 | L10: 216 | M10: 3339 | N10: 273 | O10: 136 | P10: 137 | Q10: 63 | R10: 3003 | S10: 344 | T10: 1883 | U10: 777 | V10: 919 | W10: 0 | X10: 201 | Y10: 132 | Z10: 123 | AA10: 1105 | AB10: 0 | AC10: 27 | AD10: 28 | AE10: 66 | AF10: 172 | AG10: 327 | AH10: 213 | AI10: 204 | AJ10: 0 | AK10: 96 | AL10: 80 | AM10: 221 | AN10: 673 | AO10: 1254 | AP10: 415 | AQ10: 600 | AR10: 758 | AS10: 363 | AT10: 230 | AU10: 164 | AV10: 273 | AW10: 113 | AX10: 100 | AY10: 123 | AZ10: 150 | BA10: 307 | BB10: 56 | BC10: 0.56 | BD10: 69.3 | BE10: 34.3 | BF10: 47.9 | BG10: 30.4 | BH10: 272 | BI10: 35.9
